<!DOCTYPE html>
<html lang="zh_cn">
<head>
        <meta charset="utf-8" />
        <title>Hsu's Home - Bug]</title>
        <link rel="stylesheet" href="/theme/css/main.css" />
</head>

<body id="index" class="home">
        <header id="banner" class="body">
                <h1><a href="/">Hsu's Home </a></h1>
                <nav><ul>
                    <li><a href="/category/misc.html">misc</a></li>
                </ul></nav>
        </header><!-- /#banner -->

            <aside id="featured" class="body">
                <article>
                    <h1 class="entry-title"><a href="/2017-8-23-mongo-insert_many-bulkwriteerror.html">2017-8-23 mongo insert_many BulkWriteError</a></h1>
<footer class="post-info">
        <abbr class="published" title="2017-08-23T09:31:08+08:00">
                Published: Wed 23 August 2017
        </abbr>

        <address class="vcard author">
                By                         <a class="url fn" href="/author/chihwei-hsu.html">Chihwei-Hsu</a>
        </address>
<p>In <a href="/category/misc.html">misc</a>.</p>
<p>tags: <a href="/tag/python.html">[Python</a> <a href="/tag/mongo.html">mongo</a> <a href="/tag/bug.html">Bug]</a> </p>
</footer><!-- /.post-info --><h3>问题：</h3>
<blockquote>
<p>在对mongo插入数据时，报写入问题，报错信息如下：</p>
</blockquote>
<div class="highlight"><pre><span></span>Traceback (most recent call last):
  File &quot;/root/crs/call_history_crawler/worker/communicate.py&quot;, line 149, in insert_db_data
    if db[table].insert_many(data):
  File &quot;/root/crs/call_history_crawler/venv/lib/python2.7/site-packages/pymongo/collection.py&quot;, line 684, in insert_many
    blk.execute(self.write_concern.document)
  File &quot;/root/crs/call_history_crawler/venv/lib/python2.7/site-packages/pymongo/bulk.py&quot;, line 470, in execute
    return self.execute_command(sock_info, generator, write_concern)
  File &quot;/root/crs/call_history_crawler/venv/lib/python2.7/site-packages/pymongo/bulk.py&quot;, line 314, in execute_command
    raise BulkWriteError(full_result)
BulkWriteError: batch op errors occurred
</pre></div>


<!--more-->

<h3>分析</h3>
<blockquote>
<p>问题出现在，对同一文本进行多次插入，官方说法：<code>insert_many() with a list of references to a single document raises BulkWriteError</code></p>
</blockquote>
<div class="highlight"><pre><span></span>&gt;&gt;&gt; doc = {}
&gt;&gt;&gt; collection.insert_many(doc for _ in range(10))
Traceback (most recent call last):
...
pymongo.errors.BulkWriteError: batch op errors occurred
&gt;&gt;&gt; doc
{&#39;_id&#39;: ObjectId(&#39;560f171cfba52279f0b0da0c&#39;)}

&gt;&gt;&gt; docs = [{}]
&gt;&gt;&gt; collection.insert_many(docs * 10)
Traceback (most recent call last):
...
pymongo.errors.BulkWriteError: batch op errors occurred
&gt;&gt;&gt; docs
[{&#39;_id&#39;: ObjectId(&#39;560f1933fba52279f0b0da0e&#39;)}]
</pre></div>                </article>
            </aside><!-- /#featured -->
                <section id="content" class="body">
                    <h1>Other articles</h1>
                    <hr />
                    <ol id="posts-list" class="hfeed">

            <li><article class="hentry">
                <header>
                    <h1><a href="/2017-8-1-python-rrule-bug.html" rel="bookmark"
                           title="Permalink to 2017-8-1 python rrule bug">2017-8-1 python rrule bug</a></h1>
                </header>

                <div class="entry-content">
<footer class="post-info">
        <abbr class="published" title="2017-08-01T00:00:00+08:00">
                Published: Tue 01 August 2017
        </abbr>

        <address class="vcard author">
                By                         <a class="url fn" href="/author/chihwei-hsu.html">Chihwei-Hsu</a>
        </address>
<p>In <a href="/category/misc.html">misc</a>.</p>
<p>tags: <a href="/tag/python.html">[Python</a> <a href="/tag/bug.html">Bug]</a> </p>
</footer><!-- /.post-info -->                <p><code>http://dateutil.readthedocs.io/en/stable/_modules/dateutil/rrule.html</code></p>
<h3>月份日期超限 BUG</h3>
<blockquote>
<p>Per RFC section 3.3.10, recurrence instances falling on invalid dates and times are ignored rather than coerced:
Recurrence rules may generate recurrence instances with an invalid date (e.g., February 30) or nonexistent local time (e …</p></blockquote>
                <a class="readmore" href="/2017-8-1-python-rrule-bug.html">read more</a>
                </div><!-- /.entry-content -->
            </article></li>
                </ol><!-- /#posts-list -->
                </section><!-- /#content -->
        <section id="extras" class="body">
                <div class="blogroll">
                        <h2>links</h2>
                        <ul>
                            <li><a href="http://getpelican.com/">Pelican</a></li>
                            <li><a href="http://python.org/">Python.org</a></li>
                            <li><a href="http://jinja.pocoo.org/">Jinja2</a></li>
                            <li><a href="#">You can modify those links in your config file</a></li>
                        </ul>
                </div><!-- /.blogroll -->
                <div class="social">
                        <h2>social</h2>
                        <ul>

                            <li><a href="#">You can add links in your config file</a></li>
                            <li><a href="#">Another social link</a></li>
                        </ul>
                </div><!-- /.social -->
        </section><!-- /#extras -->

        <footer id="contentinfo" class="body">
                <address id="about" class="vcard body">
                Proudly powered by <a href="http://getpelican.com/">Pelican</a>, which takes great advantage of <a href="http://python.org">Python</a>.
                </address><!-- /#about -->

                <p>The theme is by <a href="http://coding.smashingmagazine.com/2009/08/04/designing-a-html-5-layout-from-scratch/">Smashing Magazine</a>, thanks!</p>
        </footer><!-- /#contentinfo -->

</body>
</html>